Workbook

Sheet FE
H1: =SUBTOTAL(101,H3:H175) -> 0.051884393 | J1: =SUBTOTAL(101,J3:J175) -> 9.9612717 | L1: =SUBTOTAL(101,L3:L175) -> 18.736994
A2: ID | B2: Pos | C2: Name | D2: T | E2: S | F2: Game Info | G2: GID | H2: Own | I2: Flr | J2: Proj | K2: 3.5X | L2: Ceil | M2: ITT | N2: Pl | O2: Notes
A3: 40470870 | B3: DST | C3: Colts | D3: IND | E3: 3800 | F3: TEN@IND 04:25PM | G3: 10 | H3: =VLOOKUP(A3, ETR!A:K, 11, FALSE) -> 0.112 | I3: =VLOOKUP(A3, ETR!A:K, 7, FALSE) -> 3.6 | J3: =VLOOKUP(A3, ETR!A:K, 8, FALSE) -> 10.2 | L3: =VLOOKUP(A3, ETR!A:K, 9, FALSE) -> 18.1 | M3: =VLOOKUP(D3,ITT!A:D,4,FALSE) -> 30.5
A4: 40470871 | B4: DST | C4: Patriots | D4: NE | E4: 3600 | F4: CLE@NE 01:00PM | G4: 3 | H4: =VLOOKUP(A4, ETR!A:K, 11, FALSE) -> 0.056 | I4: =VLOOKUP(A4, ETR!A:K, 7, FALSE) -> 2.5 | J4: =VLOOKUP(A4, ETR!A:K, 8, FALSE) -> 8.7 | L4: =VLOOKUP(A4, ETR!A:K, 9, FALSE) -> 16.3 | M4: =VLOOKUP(D4,ITT!A:D,4,FALSE) -> 23.75
A5: 40470872 | B5: DST | C5: Falcons | D5: ATL | E5: 3500 | F5: MIA@ATL 01:00PM | G5: 4 | H5: =VLOOKUP(A5, ETR!A:K, 11, FALSE) -> 0.035 | I5: =VLOOKUP(A5, ETR!A:K, 7, FALSE) -> 1.5 | J5: =VLOOKUP(A5, ETR!A:K, 8, FALSE) -> 7.3 | L5: =VLOOKUP(A5, ETR!A:K, 9, FALSE) -> 14.5 | M5: =VLOOKUP(D5,ITT!A:D,4,FALSE) -> 25.75
A6: 40470873 | B6: DST | C6: Buccaneers | D6: TB | E6: 3400 | F6: TB@NO 04:05PM | G6: 8 | H6: =VLOOKUP(A6, ETR!A:K, 11, FALSE) -> 0.028 | I6: =VLOOKUP(A6, ETR!A:K, 7, FALSE) -> 1.2 | J6: =VLOOKUP(A6, ETR!A:K, 8, FALSE) -> 7.1 | L6: =VLOOKUP(A6, ETR!A:K, 9, FALSE) -> 14.4 | M6: =VLOOKUP(D6,ITT!A:D,4,FALSE) -> 25.5
A7: 40470874 | B7: DST | C7: Bills | D7: BUF | E7: 3300 | F7: BUF@CAR 01:00PM | G7: 1 | H7: =VLOOKUP(A7, ETR!A:K, 11, FALSE) -> 0.042 | I7: =VLOOKUP(A7, ETR!A:K, 7, FALSE) -> 1.2 | J7: =VLOOKUP(A7, ETR!A:K, 8, FALSE) -> 7.1 | L7: =VLOOKUP(A7, ETR!A:K, 9, FALSE) -> 14.3 | M7: =VLOOKUP(D7,ITT!A:D,4,FALSE) -> 27
A8: 40470875 | B8: DST | C8: Eagles | D8: PHI | E8: 3200 | F8: NYG@PHI 01:00PM | G8: 5 | H8: =VLOOKUP(A8, ETR!A:K, 11, FALSE) -> 0.102 | I8: =VLOOKUP(A8, ETR!A:K, 7, FALSE) -> 2.1 | J8: =VLOOKUP(A8, ETR!A:K, 8, FALSE) -> 8.4 | L8: =VLOOKUP(A8, ETR!A:K, 9, FALSE) -> 16.1 | M8: =VLOOKUP(D8,ITT!A:D,4,FALSE) -> 25.5
A9: 40470876 | B9: DST | C9: Broncos | D9: DEN | E9: 3100 | F9: DAL@DEN 04:25PM | G9: 9 | H9: =VLOOKUP(A9, ETR!A:K, 11, FALSE) -> 0.034 | I9: =VLOOKUP(A9, ETR!A:K, 7, FALSE) -> 0 | J9: =VLOOKUP(A9, ETR!A:K, 8, FALSE) -> 5.7 | L9: =VLOOKUP(A9, ETR!A:K, 9, FALSE) -> 12.7 | M9: =VLOOKUP(D9,ITT!A:D,4,FALSE) -> 27
A10: 40470877 | B10: DST | C10: Texans | D10: HOU | E10: 3000 | F10: SF@HOU 01:00PM | G10: 7 | H10: =VLOOKUP(A10, ETR!A:K, 11, FALSE) -> 0.057 | I10: =VLOOKUP(A10, ETR!A:K, 7, FALSE) -> 1 | J10: =VLOOKUP(A10, ETR!A:K, 8, FALSE) -> 6.6 | L10: =VLOOKUP(A10, ETR!A:K, 9, FALSE) -> 13.7 | M10: =VLOOKUP(D10,ITT!A:D,4,FALSE) -> 21.5
A11: 40470878 | B11: DST | C11: 49ers | D11: SF | E11: 2900 | F11: SF@HOU 01:00PM | G11: 7 | H11: =VLOOKUP(A11, ETR!A:K, 11, FALSE) -> 0.049 | I11: =VLOOKUP(A11, ETR!A:K, 7, FALSE) -> 1.1 | J11: =VLOOKUP(A11, ETR!A:K, 8, FALSE) -> 7.1 | L11: =VLOOKUP(A11, ETR!A:K, 9, FALSE) -> 14.4 | M11: =VLOOKUP(D11,ITT!A:D,4,FALSE) -> 20
A12: 40470879 | B12: DST | C12: Ravens | D12: BAL | E12: 2800 | F12: CHI@BAL 01:00PM | G12: 2 | H12: =VLOOKUP(A12, ETR!A:K, 11, FALSE) -> 0.058 | I12: =VLOOKUP(A12, ETR!A:K, 7, FALSE) -> 1 | J12: =VLOOKUP(A12, ETR!A:K, 8, FALSE) -> 6.9 | L12: =VLOOKUP(A12, ETR!A:K, 9, FALSE) -> 14.2 | M12: =VLOOKUP(D12,ITT!A:D,4,FALSE) -> 25
A13: 40470880 | B13: DST | C13: Bengals | D13: CIN | E13: 2700 | F13: NYJ@CIN 01:00PM | G13: 6 | H13: =VLOOKUP(A13, ETR!A:K, 11, FALSE) -> 0.142 | I13: =VLOOKUP(A13, ETR!A:K, 7, FALSE) -> 2 | J13: =VLOOKUP(A13, ETR!A:K, 8, FALSE) -> 7.9 | L13: =VLOOKUP(A13, ETR!A:K, 9, FALSE) -> 15.1 | M13: =VLOOKUP(D13,ITT!A:D,4,FALSE) -> 25.5 | O13: Chalk
A14: 40470881 | B14: DST | C14: Bears | D14: CHI | E14: 2600 | F14: CHI@BAL 01:00PM | G14: 2 | H14: =VLOOKUP(A14, ETR!A:K, 11, FALSE) -> 0.03 | I14: =VLOOKUP(A14, ETR!A:K, 7, FALSE) -> 0.5 | J14: =VLOOKUP(A14, ETR!A:K, 8, FALSE) -> 6.1 | L14: =VLOOKUP(A14, ETR!A:K, 9, FALSE) -> 12.9 | M14: =VLOOKUP(D14,ITT!A:D,4,FALSE) -> 21.5
A15: 40470882 | B15: DST | C15: Browns | D15: CLE | E15: 2500 | F15: CLE@NE 01:00PM | G15: 3 | H15: =VLOOKUP(A15, ETR!A:K, 11, FALSE) -> 0.065 | I15: =VLOOKUP(A15, ETR!A:K, 7, FALSE) -> 0.7 | J15: =VLOOKUP(A15, ETR!A:K, 8, FALSE) -> 6.7 | L15: =VLOOKUP(A15, ETR!A:K, 9, FALSE) -> 13.8 | M15: =VLOOKUP(D15,ITT!A:D,4,FALSE) -> 16.75
A16: 40470883 | B16: DST | C16: Cowboys | D16: DAL | E16: 2400 | F16: DAL@DEN 04:25PM | G16: 9 | H16: =VLOOKUP(A16, ETR!A:K, 11, FALSE) -> 0.013 | I16: =VLOOKUP(A16, ETR!A:K, 7, FALSE) -> -1.2 | J16: =VLOOKUP(A16, ETR!A:K, 8, FALSE) -> 4.3 | L16: =VLOOKUP(A16, ETR!A:K, 9, FALSE) -> 10.9 | M16: =VLOOKUP(D16,ITT!A:D,4,FALSE) -> 23.5
A17: 40470885 | B17: DST | C17: Jets | D17: NYJ | E17: 2300 | F17: NYJ@CIN 01:00PM | G17: 6 | H17: =VLOOKUP(A17, ETR!A:K, 11, FALSE) -> 0.041 | I17: =VLOOKUP(A17, ETR!A:K, 7, FALSE) -> -0.2 | J17: =VLOOKUP(A17, ETR!A:K, 8, FALSE) -> 5.4 | L17: =VLOOKUP(A17, ETR!A:K, 9, FALSE) -> 12.3 | M17: =VLOOKUP(D17,ITT!A:D,4,FALSE) -> 19
A18: 40470884 | B18: DST | C18: Saints | D18: NO | E18: 2300 | F18: TB@NO 04:05PM | G18: 8 | H18: =VLOOKUP(A18, ETR!A:K, 11, FALSE) -> 0.038 | I18: =VLOOKUP(A18, ETR!A:K, 7, FALSE) -> -0.6 | J18: =VLOOKUP(A18, ETR!A:K, 8, FALSE) -> 5 | L18: =VLOOKUP(A18, ETR!A:K, 9, FALSE) -> 11.8 | M18: =VLOOKUP(D18,ITT!A:D,4,FALSE) -> 21
A19: 40470887 | B19: DST | C19: Panthers | D19: CAR | E19: 2200 | F19: BUF@CAR 01:00PM | G19: 1 | H19: =VLOOKUP(A19, ETR!A:K, 11, FALSE) -> 0.004 | I19: =VLOOKUP(A19, ETR!A:K, 7, FALSE) -> -1.3 | J19: =VLOOKUP(A19, ETR!A:K, 8, FALSE) -> 3.9 | L19: =VLOOKUP(A19, ETR!A:K, 9, FALSE) -> 10.2 | M19: =VLOOKUP(D19,ITT!A:D,4,FALSE) -> 19.5
A20: 40470886 | B20: DST | C20: Dolphins | D20: MIA | E20: 2200 | F20: MIA@ATL 01:00PM | G20: 4 | H20: =VLOOKUP(A20, ETR!A:K, 11, FALSE) -> 0.021 | I20: =VLOOKUP(A20, ETR!A:K, 7, FALSE) -> -0.6 | J20: =VLOOKUP(A20, ETR!A:K, 8, FALSE) -> 4.8 | L20: =VLOOKUP(A20, ETR!A:K, 9, FALSE) -> 11.3 | M20: =VLOOKUP(D20,ITT!A:D,4,FALSE) -> 18.75
A21: 40470888 | B21: DST | C21: Giants | D21: NYG | E21: 2100 | F21: NYG@PHI 01:00PM | G21: 5 | H21: =VLOOKUP(A21, ETR!A:K, 11, FALSE) -> 0.068 | I21: =VLOOKUP(A21, ETR!A:K, 7, FALSE) -> 0 | J21: =VLOOKUP(A21, ETR!A:K, 8, FALSE) -> 5.7 | L21: =VLOOKUP(A21, ETR!A:K, 9, FALSE) -> 12.5 | M21: =VLOOKUP(D21,ITT!A:D,4,FALSE) -> 18
A22: 40470889 | B22: DST | C22: Titans | D22: TEN | E22: 2000 | F22: TEN@IND 04:25PM | G22: 10 | H22: =VLOOKUP(A22, ETR!A:K, 11, FALSE) -> 0.007 | I22: =VLOOKUP(A22, ETR!A:K, 7, FALSE) -> -2.1 | J22: =VLOOKUP(A22, ETR!A:K, 8, FALSE) -> 3.1 | L22: =VLOOKUP(A22, ETR!A:K, 9, FALSE) -> 9.4 | M22: =VLOOKUP(D22,ITT!A:D,4,FALSE) -> 16
A23: 40469963 | B23: QB | C23: Josh Allen | D23: BUF | E23: 7500 | F23: BUF@CAR 01:00PM | G23: 1 | H23: =VLOOKUP(A23, ETR!A:K, 11, FALSE) -> 0.052 | I23: =VLOOKUP(A23, ETR!A:K, 7, FALSE) -> 12.3 | J23: =VLOOKUP(A23, ETR!A:K, 8, FALSE) -> 22.3 | L23: =VLOOKUP(A23, ETR!A:K, 9, FALSE) -> 33.7 | M23: =VLOOKUP(D23,ITT!A:D,4,FALSE) -> 27 | N23: Y | O23: Very hard to find a stack partner that exceeds 15 pts
A24: 40469965 | B24: QB | C24: Jalen Hurts | D24: PHI | E24: 6600 | F24: NYG@PHI 01:00PM | G24: 5 | H24: =VLOOKUP(A24, ETR!A:K, 11, FALSE) -> 0.121 | I24: =VLOOKUP(A24, ETR!A:K, 7, FALSE) -> 11.1 | J24: =VLOOKUP(A24, ETR!A:K, 8, FALSE) -> 20.7 | L24: =VLOOKUP(A24, ETR!A:K, 9, FALSE) -> 31.6 | M24: =VLOOKUP(D24,ITT!A:D,4,FALSE) -> 25.5 | O24: Don't know that I can play him with his two primary guys chalky
A25: 40469966 | B25: QB | C25: Dak Prescott | D25: DAL | E25: 6500 | F25: DAL@DEN 04:25PM | G25: 9 | H25: =VLOOKUP(A25, ETR!A:K, 11, FALSE) -> 0.029 | I25: =VLOOKUP(A25, ETR!A:K, 7, FALSE) -> 9.9 | J25: =VLOOKUP(A25, ETR!A:K, 8, FALSE) -> 19 | L25: =VLOOKUP(A25, ETR!A:K, 9, FALSE) -> 29.5 | M25: =VLOOKUP(D25,ITT!A:D,4,FALSE) -> 23.5 | N25: Y | O25: 2.5%? Whuuuuut??
A26: 40469967 | B26: QB | C26: Baker Mayfield | D26: TB | E26: 6400 | F26: TB@NO 04:05PM | G26: 8 | H26: =VLOOKUP(A26, ETR!A:K, 11, FALSE) -> 0.094 | I26: =VLOOKUP(A26, ETR!A:K, 7, FALSE) -> 11.2 | J26: =VLOOKUP(A26, ETR!A:K, 8, FALSE) -> 20.6 | L26: =VLOOKUP(A26, ETR!A:K, 9, FALSE) -> 31.7 | M26: =VLOOKUP(D26,ITT!A:D,4,FALSE) -> 25.5 | N26: Y
A27: 40469968 | B27: QB | C27: Drake Maye | D27: NE | E27: 6200 | F27: CLE@NE 01:00PM | G27: 3 | H27: =VLOOKUP(A27, ETR!A:K, 11, FALSE) -> 0.047 | I27: =VLOOKUP(A27, ETR!A:K, 7, FALSE) -> 10.6 | J27: =VLOOKUP(A27, ETR!A:K, 8, FALSE) -> 19.7 | L27: =VLOOKUP(A27, ETR!A:K, 9, FALSE) -> 30.1 | M27: =VLOOKUP(D27,ITT!A:D,4,FALSE) -> 23.75 | N27: Y | O27: 4.5%? Whuuuuut??
A28: 40469969 | B28: QB | C28: Daniel Jones | D28: IND | E28: 6100 | F28: TEN@IND 04:25PM | G28: 10 | H28: =VLOOKUP(A28, ETR!A:K, 11, FALSE) -> 0.087 | I28: =VLOOKUP(A28, ETR!A:K, 7, FALSE) -> 10.9 | J28: =VLOOKUP(A28, ETR!A:K, 8, FALSE) -> 19.7 | L28: =VLOOKUP(A28, ETR!A:K, 9, FALSE) -> 31.2 | M28: =VLOOKUP(D28,ITT!A:D,4,FALSE) -> 30.5 | N28: C | O28: Don’t know if I'll get there to him this week
A29: 40469970 | B29: QB | C29: Bo Nix | D29: DEN | E29: 6000 | F29: DAL@DEN 04:25PM | G29: 9 | H29: =VLOOKUP(A29, ETR!A:K, 11, FALSE) -> 0.122 | I29: =VLOOKUP(A29, ETR!A:K, 7, FALSE) -> 12.2 | J29: =VLOOKUP(A29, ETR!A:K, 8, FALSE) -> 22.1 | L29: =VLOOKUP(A29, ETR!A:K, 9, FALSE) -> 33.3 | M29: =VLOOKUP(D29,ITT!A:D,4,FALSE) -> 27 | N29: Y
A30: 40469972 | B30: QB | C30: Caleb Williams | D30: CHI | E30: 5600 | F30: CHI@BAL 01:00PM | G30: 2 | H30: =VLOOKUP(A30, ETR!A:K, 11, FALSE) -> 0.028 | I30: =VLOOKUP(A30, ETR!A:K, 7, FALSE) -> 8.6 | J30: =VLOOKUP(A30, ETR!A:K, 8, FALSE) -> 16.8 | L30: =VLOOKUP(A30, ETR!A:K, 9, FALSE) -> 26.5 | M30: =VLOOKUP(D30,ITT!A:D,4,FALSE) -> 21.5
A31: 40469973 | B31: QB | C31: Jaxson Dart | D31: NYG | E31: 5500 | F31: NYG@PHI 01:00PM | G31: 5 | H31: =VLOOKUP(A31, ETR!A:K, 11, FALSE) -> 0.03 | I31: =VLOOKUP(A31, ETR!A:K, 7, FALSE) -> 9.2 | J31: =VLOOKUP(A31, ETR!A:K, 8, FALSE) -> 17.7 | L31: =VLOOKUP(A31, ETR!A:K, 9, FALSE) -> 27.9 | M31: =VLOOKUP(D31,ITT!A:D,4,FALSE) -> 18 | N31: C | O31: I think he does enough on his own, haven't figured out who to stack him with
A32: 40469974 | B32: QB | C32: Joe Flacco | D32: CIN | E32: 5400 | F32: NYJ@CIN 01:00PM | G32: 6 | H32: =VLOOKUP(A32, ETR!A:K, 11, FALSE) -> 0.077 | I32: =VLOOKUP(A32, ETR!A:K, 7, FALSE) -> 9.2 | J32: =VLOOKUP(A32, ETR!A:K, 8, FALSE) -> 18 | L32: =VLOOKUP(A32, ETR!A:K, 9, FALSE) -> 28.1 | M32: =VLOOKUP(D32,ITT!A:D,4,FALSE) -> 25.5
A33: 40469975 | B33: QB | C33: Mac Jones | D33: SF | E33: 5300 | F33: SF@HOU 01:00PM | G33: 7 | H33: =VLOOKUP(A33, ETR!A:K, 11, FALSE) -> 0.008 | I33: =VLOOKUP(A33, ETR!A:K, 7, FALSE) -> 7.7 | J33: =VLOOKUP(A33, ETR!A:K, 8, FALSE) -> 15.3 | L33: =VLOOKUP(A33, ETR!A:K, 9, FALSE) -> 24.6 | M33: =VLOOKUP(D33,ITT!A:D,4,FALSE) -> 20 | N33: C | O33: If I thought there was a chance he'd get 25 pts I'd play him, feels like CMC game
A34: 40469977 | B34: QB | C34: C.J. Stroud | D34: HOU | E34: 5100 | F34: SF@HOU 01:00PM | G34: 7 | H34: =VLOOKUP(A34, ETR!A:K, 11, FALSE) -> 0.057 | I34: =VLOOKUP(A34, ETR!A:K, 7, FALSE) -> 8.7 | J34: =VLOOKUP(A34, ETR!A:K, 8, FALSE) -> 16.8 | L34: =VLOOKUP(A34, ETR!A:K, 9, FALSE) -> 26.4 | M34: =VLOOKUP(D34,ITT!A:D,4,FALSE) -> 21.5 | N34: C
A35: 40469978 | B35: QB | C35: Justin Fields | D35: NYJ | E35: 5000 | F35: NYJ@CIN 01:00PM | G35: 6 | H35: =VLOOKUP(A35, ETR!A:K, 11, FALSE) -> 0.034 | I35: =VLOOKUP(A35, ETR!A:K, 7, FALSE) -> 9 | J35: =VLOOKUP(A35, ETR!A:K, 8, FALSE) -> 17.6 | L35: =VLOOKUP(A35, ETR!A:K, 9, FALSE) -> 27.9 | M35: =VLOOKUP(D35,ITT!A:D,4,FALSE) -> 19 | O35: Sources say Fields is going to start, they haven't updated his projection yet
A36: 40469980 | B36: QB | C36: Tua Tagovailoa | D36: MIA | E36: 4800 | F36: MIA@ATL 01:00PM | G36: 4 | H36: =VLOOKUP(A36, ETR!A:K, 11, FALSE) -> 0.002 | I36: =VLOOKUP(A36, ETR!A:K, 7, FALSE) -> 6.4 | J36: =VLOOKUP(A36, ETR!A:K, 8, FALSE) -> 13.6 | L36: =VLOOKUP(A36, ETR!A:K, 9, FALSE) -> 22.1 | M36: =VLOOKUP(D36,ITT!A:D,4,FALSE) -> 18.75
A37: 40469981 | B37: QB | C37: Spencer Rattler | D37: NO | E37: 4700 | F37: TB@NO 04:05PM | G37: 8 | H37: =VLOOKUP(A37, ETR!A:K, 11, FALSE) -> 0.086 | I37: =VLOOKUP(A37, ETR!A:K, 7, FALSE) -> 8.8 | J37: =VLOOKUP(A37, ETR!A:K, 8, FALSE) -> 16.9 | L37: =VLOOKUP(A37, ETR!A:K, 9, FALSE) -> 26.8 | M37: =VLOOKUP(D37,ITT!A:D,4,FALSE) -> 21
A38: 40469982 | B38: QB | C38: Cam Ward | D38: TEN | E38: 4600 | F38: TEN@IND 04:25PM | G38: 10 | H38: =VLOOKUP(A38, ETR!A:K, 11, FALSE) -> 0.003 | I38: =VLOOKUP(A38, ETR!A:K, 7, FALSE) -> 6.2 | J38: =VLOOKUP(A38, ETR!A:K, 8, FALSE) -> 13.1 | L38: =VLOOKUP(A38, ETR!A:K, 9, FALSE) -> 21.4 | M38: =VLOOKUP(D38,ITT!A:D,4,FALSE) -> 16
A39: 40469983 | B39: QB | C39: Andy Dalton | D39: CAR | E39: 4500 | F39: BUF@CAR 01:00PM | G39: 1 | H39: =VLOOKUP(A39, ETR!A:K, 11, FALSE) -> 0.009 | I39: =VLOOKUP(A39, ETR!A:K, 7, FALSE) -> 6.6 | J39: =VLOOKUP(A39, ETR!A:K, 8, FALSE) -> 13.9 | L39: =VLOOKUP(A39, ETR!A:K, 9, FALSE) -> 22.2 | M39: =VLOOKUP(D39,ITT!A:D,4,FALSE) -> 19.5 | N39: C
A40: 40469985 | B40: QB | C40: Kirk Cousins | D40: ATL | E40: 4400 | F40: MIA@ATL 01:00PM | G40: 4 | H40: =VLOOKUP(A40, ETR!A:K, 11, FALSE) -> 0.073 | I40: =VLOOKUP(A40, ETR!A:K, 7, FALSE) -> 8 | J40: =VLOOKUP(A40, ETR!A:K, 8, FALSE) -> 15.7 | L40: =VLOOKUP(A40, ETR!A:K, 9, FALSE) -> 25.8 | M40: =VLOOKUP(D40,ITT!A:D,4,FALSE) -> 25.75
...

Sheet ETR
A1: id | B1: Player | C1: DK Pos | D1: Team | E1: Opp | F1: DK Salary | G1: DK Floor | H1: DK Proj | I1: DK Ceiling | J1: DK Value | K1: Large Field
A2: 40469963 | B2: Josh Allen | C2: QB | D2: BUF | E2: @CAR | F2: 7500 | G2: 12.3 | H2: 22.3 | I2: 33.7 | J2: -0.9 | K2: 0.052
A3: 40469965 | B3: Jalen Hurts | C3: QB | D3: PHI | E3: NYG | F3: 6600 | G3: 11.1 | H3: 20.7 | I3: 31.6 | J3: 0.3 | K3: 0.121
A4: 40469966 | B4: Dak Prescott | C4: QB | D4: DAL | E4: @DEN | F4: 6500 | G4: 9.9 | H4: 19 | I4: 29.5 | J4: -1.1 | K4: 0.029
A5: 40469967 | B5: Baker Mayfield | C5: QB | D5: TB | E5: @NO | F5: 6400 | G5: 11.2 | H5: 20.6 | I5: 31.7 | J5: 0.8 | K5: 0.094
A6: 40469968 | B6: Drake Maye | C6: QB | D6: NE | E6: CLE | F6: 6200 | G6: 10.6 | H6: 19.7 | I6: 30.1 | J6: 0.5 | K6: 0.047
A7: 40469969 | B7: Daniel Jones | C7: QB | D7: IND | E7: TEN | F7: 6100 | G7: 10.9 | H7: 19.7 | I7: 31.2 | J7: 0.8 | K7: 0.087
A8: 40469970 | B8: Bo Nix | C8: QB | D8: DEN | E8: DAL | F8: 6000 | G8: 12.2 | H8: 22.1 | I8: 33.3 | J8: 3.5 | K8: 0.122
A9: 40469972 | B9: Caleb Williams | C9: QB | D9: CHI | E9: @BAL | F9: 5600 | G9: 8.6 | H9: 16.8 | I9: 26.5 | J9: -0.6 | K9: 0.028
A10: 40469973 | B10: Jaxson Dart | C10: QB | D10: NYG | E10: @PHI | F10: 5500 | G10: 9.2 | H10: 17.7 | I10: 27.9 | J10: 0.6 | K10: 0.03
A11: 40469974 | B11: Joe Flacco | C11: QB | D11: CIN | E11: NYJ | F11: 5400 | G11: 9.2 | H11: 18 | I11: 28.1 | J11: 1.2 | K11: 0.077
A12: 40469975 | B12: Mac Jones | C12: QB | D12: SF | E12: @HOU | F12: 5300 | G12: 7.7 | H12: 15.3 | I12: 24.6 | J12: -1.2 | K12: 0.008
A13: 40469977 | B13: C.J. Stroud | C13: QB | D13: HOU | E13: SF | F13: 5100 | G13: 8.7 | H13: 16.8 | I13: 26.4 | J13: 1 | K13: 0.057
... A268: 40470889 | B268: Titans | C268: DST | D268: TEN | E268: @IND | F268: 2000 | G268: -2.1 | H268: 3.1 | I268: 9.4 | J268: -1.9 | K268: 0.007

Sheet ITT
A1: Tm Ab | B1: Rk | C1: Team | D1: ITT | E1: Spread | F1: OU | G1: Opp
A2: IND | B2: 1 | C2: Indianapolis Colts | D2: 30.5 | E2: -14.5 | F2: 46.5 | G2: Tennessee Titans
A3: KC | B3: 2 | C3: Kansas City Chiefs | D3: 29.5 | E3: -11.5 | F3: 47.5 | G3: Washington Commanders
A4: BAL | B4: 9 | C4: Baltimore Ravens | D4: 25 | E4: -3.5 | F4: 46.5 | G4: Chicago Bears
A5: BUF | B5: 3 | C5: Buffalo Bills | D5: 27 | E5: -7.5 | F5: 46.5 | G5: Carolina Panthers
A6: DEN | B6: 3 | C6: Denver Broncos | D6: 27 | E6: -3.5 | F6: 50.5 | G6: Dallas Cowboys
A7: ATL | B7: 5 | C7: Atlanta Falcons | D7: 25.75 | E7: -7 | F7: 44.5 | G7: Miami Dolphins
A8: TB | B8: 6 | C8: Tampa Bay Buccaneers | D8: 25.5 | E8: -4.5 | F8: 46.5 | G8: New Orleans Saints
A9: PHI | B9: 6 | C9: Philadelphia Eagles | D9: 25.5 | E9: -7.5 | F9: 43.5 | G9: New York Giants
A10: CIN | B10: 6 | C10: Cincinnati Bengals | D10: 25.5 | E10: -6.5 | F10: 44.5 | G10: New York Jets
A11: GB | B11: 10 | C11: Green Bay Packers | D11: 24.25 | E11: -3 | F11: 45.5 | G11: Pittsburgh Steelers
A12: LAC | B12: 11 | C12: Los Angeles Chargers | D12: 23.75 | E12: -3 | F12: 44.5 | G12: Minnesota Vikings
A13: NE | B13: 11 | C13: New England Patriots | D13: 23.75 | E13: -7 | F13: 40.5 | G13: Cleveland Browns
... A27: TEN | B27: 26 | C27: Tennessee Titans | D27: 16 | E27: 14.5 | F27: 46.5 | G27: Indianapolis Colts

Sheet Stacks
B1: Stacks | J1: Backs | R1: One off cracks
A2: Pos | B2: Name | C2: Tm | D2: Sal | E2: Own | F2: Proj | G2: Ceil | I2: Pos | J2: Name | K2: Tm | L2: Sal | M2: Own | N2: Proj | O2: Ceil | Q2: Pos | R2: Name | S2: Tm | T2: Sal | U2: Own | V2: Proj | W2: Ceil
A3: QB | B3: Josh Allen | C3: BUF | D3: 7500 | E3: 0.052 | F3: 22.3 | G3: 33.7 | I3: RB | J3: Jonathan Taylor | K3: IND | L3: 9500 | M3: 0.227 | N3: 25.8 | O3: 41.7 | Q3: WR | R3: Rome Odunze | S3: CHI | T3: 6300 | U3: 0.06 | V3: 12.8 | W3: 24.6
A4: TE | B4: Dalton Kincaid | C4: BUF | D4: 4300 | E4: 0.034 | F4: 9.2 | G4: 18.1 | I4: RB | J4: Bijan Robinson | K4: ATL | L4: 8800 | M4: 0.291 | N4: 25.7 | O4: 41.7 | Q4: WR | R4: Tetairoa McMillan | S4: CAR | T4: 5700 | U4: 0.077 | V4: 12.9 | W4: 24.4
A5: WR | B5: Khalil Shakir | C5: BUF | D5: 5100 | E5: 0.069 | F5: 11.8 | G5: 22.5 | I5: RB | J5: Christian McCaffrey | K5: SF | L5: 9000 | M5: 0.166 | N5: 23.3 | O5: 37.5 | Q5: TE | R5: Mark Andrews | S5: BAL | T5: 3600 | U5: 0.02 | V5: 7.3 | W5: 14.9
D6: =AVERAGE(D3:D5) -> 5633.3333 | E6: =AVERAGE(E3:E5) -> 0.051666667 | F6: =AVERAGE(F3:F5) -> 14.433333 | G6: =AVERAGE(G3:G5) -> 24.766667 | I6: RB | J6: Saquon Barkley | K6: PHI | L6: 7600 | M6: 0.177 | N6: 20.6 | O6: 34.9
I7: RB | J7: De'Von Achane | K7: MIA | L7: 7300 | M7: 0.187 | N7: 19.7 | O7: 32.4
A8: QB | B8: Dak Prescott | C8: DAL | D8: 6500 | E8: 0.029 | F8: 19 | G8: 29.5 | I8: RB | J8: Javonte Williams | K8: DAL | L8: 6800 | M8: 0.096 | N8: 17.5 | O8: 30.4
A9: TE | B9: Jake Ferguson | C9: DAL | D9: 6000 | E9: 0.014 | F9: 10.8 | G9: 19.5 | I9: RB | J9: James Cook III | K9: BUF | L9: 6700 | M9: 0.118 | N9: 18.3 | O9: 32.1
A10: WR | B10: CeeDee Lamb | C10: DAL | D10: 7800 | E10: 0.1 | F10: 19.5 | G10: 34 | I10: RB | J10: Cam Skattebo | K10: NYG | L10: 6600 | M10: 0.041 | N10: 13.5 | O10: 24.3
A11: WR | B11: George Pickens | C11: DAL | D11: 7100 | E11: 0.054 | F11: 14.5 | G11: 27.5
D12: =AVERAGE(D8:D11) -> 6850 | E12: =AVERAGE(E8:E11) -> 0.04925 | F12: =AVERAGE(F8:F11) -> 15.95 | G12: =AVERAGE(G8:G11) -> 27.625
A14: QB | B14: Bo Nix | C14: DEN | D14: 6000 | E14: 0.122 | F14: 22.1 | G14: 33.3
A15: WR | B15: Courtland Sutton | C15: DEN | D15: 6200 | E15: 0.122 | F15: 14.3 | G15: 27.3
A16: WR | B16: Troy Franklin | C16: DEN | D16: 4200 | E16: 0.076 | F16: 10.1 | G16: 20.4
D17: =AVERAGE(D14:D16) -> 5466.6667 | E17: =AVERAGE(E14:E16) -> 0.10666667 | F17: =AVERAGE(F14:F16) -> 15.5 | G17: =AVERAGE(G14:G16) -> 27
A19: QB | B19: Daniel Jones | C19: IND | D19: 6100 | E19: 0.087 | F19: 19.7 | G19: 31.2
A20: TE | B20: Tyler Warren | C20: IND | D20: 5500 | E20: 0.12 | F20: 14.4 | G20: 26.3
A21: WR | B21: Michael Pittman Jr. | C21: IND | D21: 5600 | E21: 0.09 | F21: 12.8 | G21: 24.8
D22: =AVERAGE(D19:D21) -> 5733.3333 | E22: =AVERAGE(E19:E21) -> 0.099 | F22: =AVERAGE(F19:F21) -> 15.633333 | G22: =AVERAGE(G19:G21) -> 27.433333
A24: QB | B24: Mac Jones | C24: SF | D24: 5300 | E24: 0.008 | F24: 15.3 | G24: 24.6
A25: TE | B25: George Kittle | C25: SF | D25: 4500 | E25: 0.103 | F25: 12.8 | G25: 23.8
D26: =AVERAGE(D24:D25) -> 4900 | E26: =AVERAGE(E24:E25) -> 0.0555 | F26: =AVERAGE(F24:F25) -> 14.05 | G26: =AVERAGE(G24:G25) -> 24.2
A28: QB | B28: Drake Maye | C28: NE | D28: 6200 | E28: 0.047 | F28: 19.7 | G28: 30.1
A29: WR | B29: Stefon Diggs | C29: NE | D29: 5800 | E29: 0.108 | F29: 14.4 | G29: 26.7
A30: WR | B30: Kayshon Boutte | C30: NE | D30: 4800 | E30: 0.007 | F30: 7.9 | G30: 17.5
D31: =AVERAGE(D28:D30) -> 5600 | E31: =AVERAGE(E28:E30) -> 0.054 | F31: =AVERAGE(F28:F30) -> 14 | G31: =AVERAGE(G28:G30) -> 24.766667
A33: QB | B33: Spencer Rattler | C33: NO | D33: 4700 | E33: 0.086 | F33: 16.9 | G33: 26.8
A34: WR | B34: Chris Olave | C34: NO | D34: 5800 | E34: 0.209 | F34: 15.8 | G34: 28.2
A35: WR | B35: Rashid Shaheed | C35: NO | D35: 4700 | E35: 0.123 | F35: 12.5 | G35: 23.7
D36: =AVERAGE(D33:D35) -> 5066.6667 | E36: =AVERAGE(E33:E35) -> 0.13933333 | F36: =AVERAGE(F33:F35) -> 15.066667 | G36: =AVERAGE(G33:G35) -> 26.233333
A38: QB | B38: Jaxson Dart | C38: NYG | D38: 5500 | E38: 0.03 | F38: 17.7 | G38: 27.9
A39: TE | B39: Theo Johnson | C39: NYG | D39: 3700 | E39: 0.028 | F39: 8.9 | G39: 17.2
A40: WR | B40: Wan'Dale Robinson | C40: NYG | D40: 5200 | E40: 0.08 | F40: 12.4 | G40: 23
D41: =AVERAGE(D38:D40) -> 4800 | E41: =AVERAGE(E38:E40) -> 0.046 | F41: =AVERAGE(F38:F40) -> 13 | G41: =AVERAGE(G38:G40) -> 22.7
A43: QB | B43: Justin Fields | C43: NYJ | D43: 5000 | E43: 0.034 | F43: 17.6 | G43: 27.9
A44: TE | B44: Mason Taylor | C44: NYJ | D44: 3500 | E44: 0.07 | F44: 10 | G44: 18.3
D45: =AVERAGE(D43:D44) -> 4250 | E45: =AVERAGE(E43:E44) -> 0.052 | F45: =AVERAGE(F43:F44) -> 13.8 | G45: =AVERAGE(G43:G44) -> 23.1
A47: QB | B47: Jalen Hurts | C47: PHI | D47: 6600 | E47: 0.121 | F47: 20.7 | G47: 31.6
A48: TE | B48: Dallas Goedert | C48: PHI | D48: 4200 | E48: 0.196 | F48: 13.7 | G48: 24.6
...
